Workbook
Name Energy_Consumption__MWh: 'Advance Function & Outliers'!$H$2:$H$2001
Name Production_Volume__units: 'Advance Function & Outliers'!$G$2:$G$2001
Name Waste__tons: 'Advance Function & Outliers'!$I$2:$I$2001

Sheet Emission Data
A1: Facility ID | B1: Facility Name | C1: Reporting Period | D1: Scope | E1: GHG Type | F1: Emissions (tons)
A2: F088 | B2: JSW Energy | C2: 2022 Q1 | D2: Scope 3 | E2: CH₄ | F2: 2435.5974
A3: F021 | B3: L&T | C3: 2022 Q2 | D3: Scope 1 | E3: CO₂ | F3: 835.45
A4: F107 | B4: Reliance Industries | C4: 2022 Q2 | D4: Scope 1 | E4: CO₂ | F4: 3430.45
A5: F106 | B5: Tata Steel | C5: 2022 Q1 | D5: Scope 1 | E5: CO₂ | F5: 4214.24
A6: F090 | B6: Reliance Industries | C6: 2022 Q2 | D6: Scope 3 | E6: CH₄ | F6: 605.59355
A7: F158 | B7: Tata Steel | C7: 2022 Q2 | D7: Scope 1 | E7: CH₄ | F7: 656.33
A8: F023 | B8: L&T | C8: 2023 Q2 | D8: Scope 3 | E8: N₂O | F8: 4455.9341
A9: F153 | B9: Tata Steel | C9: 2022 Q2 | D9: Scope 3 | E9: CH₄ | F9: 660.19754
A10: F079 | B10: Reliance Industries | C10: 2023 Q2 | D10: Scope 3 | E10: CH₄ | F10: 1883.3043
A11: F065 | B11: L&T | C11: 2022 Q1 | D11: Scope 2 | E11: N₂O | F11: 221.01
A12: F025 | B12: Adani Green | C12: 2022 Q1 | D12: Scope 2 | E12: CH₄ | F12: 4737.06
A13: F104 | B13: Adani Green | C13: 2022 Q1 | D13: Scope 3 | E13: N₂O | F13: 1951.279
... A2001: F018 | B2001: Adani Green | C2001: 2023 Q1 | D2001: Scope 2 | E2001: N₂O | F2001: 2433.04

Sheet Operational Data
A1: Facility ID | B1: Facility Name | C1: Production Volume (units) | D1: Energy Consumption (MWh) | E1: Waste (tons)
A2: F001 | B2: L&T | C2: 54133 | D2: 8543.68 | E2: 24
A3: F002 | B3: Adani Green | C3: 53661 | D3: 6965.81 | E3: 69.4
A4: F003 | B4: Tata Steel | C4: 27681 | D4: 928.26 | E4: 44.97
A5: F004 | B5: JSW Energy | C5: 83923 | D5: 8768.8 | E5: 65.29
A6: F005 | B6: Adani Green | C6: 61743 | D6: 7426.75 | E6: 26.39
A7: F006 | B7: Adani Green | C7: 11426 | D7: 4439.56 | E7: 52.71
A8: F007 | B8: Adani Green | C8: 35506 | D8: 1892.04 | E8: 61.53
A9: F008 | B9: Tata Steel | C9: 50306 | D9: 7031.37 | E9: 13.27
A10: F009 | B10: JSW Energy | C10: 45644 | D10: 7724.73 | E10: 31
A11: F010 | B11: JSW Energy | C11: 32991 | D11: 8540.14 | E11: 37.75
A12: F011 | B12: Adani Green | C12: 72846 | D12: 5169.53 | E12: 76.71
A13: F012 | B13: Tata Steel | C13: 43747 | D13: 3453.48 | E13: 98.78
... A201: F200 | B201: L&T | C201: 21081 | D201: 9001.77 | E201: 49.27

Sheet Supplier Data
A1: Supplier ID | B1: Estimated Carbon Footprint (tons CO₂e) | C1: Income Distribution (%)
A2: S001 | B2: 959.2 | C2: {'F090': 38.84, 'F082': 36.92, 'F147': 24.24}
A3: S002 | B3: 231.68 | C3: {'F143': 13.88, 'F082': 10.02, 'F057': 15.92, 'F150': 35.92, 'F056': 24.26}
A4: S003 | B4: 714.03 | C4: {'F172': 36.89, 'F176': 32.29, 'F027': 10.84, 'F163': 19.98}
A5: S004 | B5: 571.88 | C5: {'F157': 8.17, 'F100': 20.93, 'F136': 32.18, 'F132': 30.1, 'F067': 8.62}
A6: S005 | B6: 114.57 | C6: {'F092': 9.83, 'F200': 44.17, 'F072': 36.04, 'F173': 9.96}
A7: S006 | B7: 790.74 | C7: {'F023': 12.77, 'F192': 15.07, 'F189': 15.94, 'F169': 27.44, 'F118': 28.78}
A8: S007 | B8: 847.51 | C8: {'F145': 7.14, 'F170': 26.48, 'F022': 28.45, 'F015': 9.9, 'F151': 28.03}
A9: S008 | B9: 610.8 | C9: {'F002': 29.15, 'F104': 26.58, 'F059': 14.23, 'F066': 30.04}
A10: S009 | B10: 390.06 | C10: {'F154': 18.01, 'F109': 27.42, 'F044': 23.14, 'F193': 31.43}
A11: S010 | B11: 932.3 | C11: {'F084': 16.93, 'F027': 30.55, 'F198': 10.19, 'F040': 13.43, 'F101': 28.9}
A12: S011 | B12: 795.74 | C12: {'F151': 22.49, 'F179': 18.73, 'F103': 26.99, 'F171': 22.41, 'F180': 9.39}
A13: S012 | B13: 986.62 | C13: {'F013': 42.1, 'F111': 17.04, 'F054': 40.86}
... A101: S100 | B101: 169.33 | C101: {'F184': 52.13, 'F170': 47.87}

Sheet Regulatory Benchmarks
A1: Benchmark | B1: Value | C1: Description
A2: GHG Reduction Target | B2: 25% reduction | C2: Company must reduce overall GHG emissions by 25% over the next 5 years.
A3: Net Zero Milestone | B3: 2050 | C3: Target year to achieve net zero emissions.
A4: Emission Reporting Standard | B4: GHG Protocol | C4: All emissions must be reported according to the GHG Protocol guidelines.

Sheet Emission
A1: Facility ID | B1: Facility Name | C1: Reporting Period | D1: Scope | E1: GHG Type | F1: Emissions (tons) | G1: Year
A2: F088 | B2: JSW Energy | C2: 2022 Q1 | D2: Scope 3 | E2: CH₄ | F2: 2435.6 | G2: 2022
A3: F021 | B3: L&T | C3: 2022 Q2 | D3: Scope 1 | E3: CO₂ | F3: 835.45 | G3: 2022
A4: F107 | B4: Reliance Industries | C4: 2022 Q2 | D4: Scope 1 | E4: CO₂ | F4: 3430.45 | G4: 2022
A5: F106 | B5: Tata Steel | C5: 2022 Q1 | D5: Scope 1 | E5: CO₂ | F5: 4214.24 | G5: 2022
A6: F090 | B6: Reliance Industries | C6: 2022 Q2 | D6: Scope 3 | E6: CH₄ | F6: 605.59 | G6: 2022
A7: F158 | B7: Tata Steel | C7: 2022 Q2 | D7: Scope 1 | E7: CH₄ | F7: 656.33 | G7: 2022
A8: F023 | B8: L&T | C8: 2023 Q2 | D8: Scope 3 | E8: N₂O | F8: 4455.93 | G8: 2023
A9: F153 | B9: Tata Steel | C9: 2022 Q2 | D9: Scope 3 | E9: CH₄ | F9: 660.2 | G9: 2022
A10: F079 | B10: Reliance Industries | C10: 2023 Q2 | D10: Scope 3 | E10: CH₄ | F10: 1883.3 | G10: 2023
A11: F065 | B11: L&T | C11: 2022 Q1 | D11: Scope 2 | E11: N₂O | F11: 221.01 | G11: 2022
A12: F025 | B12: Adani Green | C12: 2022 Q1 | D12: Scope 2 | E12: CH₄ | F12: 4737.06 | G12: 2022
A13: F104 | B13: Adani Green | C13: 2022 Q1 | D13: Scope 3 | E13: N₂O | F13: 1951.28 | G13: 2022
... A2001: F018 | B2001: Adani Green | C2001: 2023 Q1 | D2001: Scope 2 | E2001: N₂O | F2001: 2433.04 | G2001: 2023

Sheet Operational
A1: Facility ID | B1: Facility Name | C1: Production Volume (units) | D1: Energy Consumption (MWh) | E1: Waste (tons)
A2: F001 | B2: L&T | C2: 54133 | D2: 8543.68 | E2: 24
A3: F002 | B3: Adani Green | C3: 53661 | D3: 6965.81 | E3: 69.4
A4: F003 | B4: Tata Steel | C4: 27681 | D4: 928.26 | E4: 44.97
A5: F004 | B5: JSW Energy | C5: 83923 | D5: 8768.8 | E5: 65.29
A6: F005 | B6: Adani Green | C6: 61743 | D6: 7426.75 | E6: 26.39
A7: F006 | B7: Adani Green | C7: 11426 | D7: 4439.56 | E7: 52.71
A8: F007 | B8: Adani Green | C8: 35506 | D8: 1892.04 | E8: 61.53
A9: F008 | B9: Tata Steel | C9: 50306 | D9: 7031.37 | E9: 13.27
A10: F009 | B10: JSW Energy | C10: 45644 | D10: 7724.73 | E10: 31
A11: F010 | B11: JSW Energy | C11: 32991 | D11: 8540.14 | E11: 37.75
A12: F011 | B12: Adani Green | C12: 72846 | D12: 5169.53 | E12: 76.71
A13: F012 | B13: Tata Steel | C13: 43747 | D13: 3453.48 | E13: 98.78
... A201: F200 | B201: L&T | C201: 21081 | D201: 9001.77 | E201: 49.27

Sheet Suppliar
A1: Facility ID | B1: Supplier ID | C1: Estimated Carbon Footprint (tons CO₂e) | D1: Income Distribution (%)
A2: F090 | B2: S001 | C2: 959.2 | D2: 38.84
A3: F082 | B3: S001 | C3: 959.2 | D3: 36.92
A4: F147 | B4: S001 | C4: 959.2 | D4: 24.24
A5: F143 | B5: S002 | C5: 231.68 | D5: 13.88
A6: F082 | B6: S002 | C6: 231.68 | D6: 10.02
A7: F057 | B7: S002 | C7: 231.68 | D7: 15.92
A8: F150 | B8: S002 | C8: 231.68 | D8: 35.92
A9: F056 | B9: S002 | C9: 231.68 | D9: 24.26
A10: F172 | B10: S003 | C10: 714.03 | D10: 36.89
A11: F176 | B11: S003 | C11: 714.03 | D11: 32.29
A12: F027 | B12: S003 | C12: 714.03 | D12: 10.84
A13: F163 | B13: S003 | C13: 714.03 | D13: 19.98
... A364: F170 | B364: S100 | C364: 169.33 | D364: 47.87

Sheet Pivot Table & chart
A1: 1. Emissions by Facility | D1: 2. Reporting Period | K1: 3. Emissions by scope | Q1: 4. Emissions by Year | V1: 5. Facility & scope by Emissions
A3: Row Labels | B3: Sum of Emissions (tons) | D3: Sum of Emissions (tons) | E3: Column Labels | K3: Row Labels | L3: Sum of Emissions (tons) | Q3: Row Labels | R3: Sum of Emissions (tons) | V3: Sum of Emissions (tons) | W3: Column Labels
A4: Adani Green | B4: 1361113.3 | D4: Row Labels | E4: 2022 Q1 | F4: 2022 Q2 | G4: 2023 Q1 | H4: 2023 Q2 | I4: Grand Total | K4: Scope 3 | L4: 1766860.3 | Q4: 2022 | R4: 2613289.1 | V4: Row Labels | W4: Scope 1 | X4: Scope 2 | Y4: Scope 3 | Z4: Grand Total
A5: Tata Steel | B5: 1128000.1 | D5: Adani Green | E5: 340708.9 | F5: 326256.6 | G5: 360843.22 | H5: 333304.58 | I5: 1361113.3 | K5: Scope 1 | L5: 1763843.5 | Q5: 2023 | R5: 2603102.9 | V5: Adani Green | W5: 472128.33 | X5: 450934.48 | Y5: 438050.49 | Z5: 1361113.3
A6: Reliance Industries | B6: 964689.57 | D6: Tata Steel | E6: 259864.56 | F6: 306288.8 | G6: 300529.85 | H6: 261316.87 | I6: 1128000.1 | K6: Scope 2 | L6: 1685688.1 | Q6: Grand Total | R6: 5216392 | V6: Tata Steel | W6: 402291.23 | X6: 335605.63 | Y6: 390103.22 | Z6: 1128000.1
A7: JSW Energy | B7: 946514.45 | D7: Reliance Industries | E7: 263715.99 | F7: 229041.97 | G7: 252643.39 | H7: 219288.22 | I7: 964689.57 | K7: Grand Total | L7: 5216392 | V7: Reliance Industries | W7: 280089.43 | X7: 325701.4 | Y7: 358898.74 | Z7: 964689.57
A8: L&T | B8: 816074.59 | D8: JSW Energy | E8: 203900.77 | F8: 284347.8 | G8: 217291.78 | H8: 240974.1 | I8: 946514.45 | Q8: Difference between these two years | S8: =GETPIVOTDATA("Emissions (tons)",$Q$3,"Year",2022)-GETPIVOTDATA("Emissions (tons)",$Q$3,"Year",2023) -> 10186.13 | V8: JSW Energy | W8: 333523.87 | X8: 320044.66 | Y8: 292945.92 | Z8: 946514.45
A9: Grand Total | B9: 5216392 | D9: L&T | E9: 188012.59 | F9: 211151.08 | G9: 214720.8 | H9: 202190.12 | I9: 816074.59 | V9: L&T | W9: 275810.67 | X9: 253401.97 | Y9: 286861.95 | Z9: 816074.59
D10: Grand Total | E10: 1256202.8 | F10: 1357086.2 | G10: 1346029 | H10: 1257073.9 | I10: 5216392 | V10: Grand Total | W10: 1763843.5 | X10: 1685688.1 | Y10: 1766860.3 | Z10: 5216392

Sheet Advance Function & Outliers
A1: Facility ID | B1: Facility Name | C1: Reporting Period | D1: Scope | E1: GHG Type | F1: Emissions (tons) | G1: Production Volume (units) | H1: Energy Consumption (MWh) | I1: Waste (tons)
A2: F088 | B2: JSW Energy | C2: 2022 Q1 | D2: Scope 3 | E2: CH₄ | F2: 2435.6 | G2: =INDEX(Operational[Production Volume (units)],MATCH(Emission8[[#This Row],[Facility ID]],Operational[Facility ID],0)) -> 77330 | H2: =INDEX(Operational[Energy Consumption (MWh)],MATCH(Emission8[[#This Row],[Facility ID]],Operational[Facility ID],0)) -> 6936.58 | I2: =INDEX(Operational[Waste (tons)],MATCH(Emission8[[#This Row],[Facility ID]],Operational[Facility ID],0)) -> 82.3 | K2: 1. Emissions (tons) Outliers by IQR
A3: F021 | B3: L&T | C3: 2022 Q2 | D3: Scope 1 | E3: CO₂ | F3: 835.45 | G3: =INDEX(Operational[Production Volume (units)],MATCH(Emission8[[#This Row],[Facility ID]],Operational[Facility ID],0)) -> 44657 | H3: =INDEX(Operational[Energy Consumption (MWh)],MATCH(Emission8[[#This Row],[Facility ID]],Operational[Facility ID],0)) -> 7867.98 | I3: =INDEX(Operational[Waste (tons)],MATCH(Emission8[[#This Row],[Facility ID]],Operational[Facility ID],0)) -> 96.01 | K3: Q1 | L3: =_xlfn.QUARTILE.EXC(Emission8[Emissions (tons)],1) -> 1396.6275
A4: F107 | B4: Reliance Industries | C4: 2022 Q2 | D4: Scope 1 | E4: CO₂ | F4: 3430.45 | G4: =INDEX(Operational[Production Volume (units)],MATCH(Emission8[[#This Row],[Facility ID]],Operational[Facility ID],0)) -> 43512 | H4: =INDEX(Operational[Energy Consumption (MWh)],MATCH(Emission8[[#This Row],[Facility ID]],Operational[Facility ID],0)) -> 5352.18 | I4: =INDEX(Operational[Waste (tons)],MATCH(Emission8[[#This Row],[Facility ID]],Operational[Facility ID],0)) -> 6.17 | K4: Q3 | L4: =_xlfn.QUARTILE.EXC(Emission8[Emissions (tons)],3) -> 3827.48
A5: F106 | B5: Tata Steel | C5: 2022 Q1 | D5: Scope 1 | E5: CO₂ | F5: 4214.24 | G5: =INDEX(Operational[Production Volume (units)],MATCH(Emission8[[#This Row],[Facility ID]],Operational[Facility ID],0)) -> 98682 | H5: =INDEX(Operational[Energy Consumption (MWh)],MATCH(Emission8[[#This Row],[Facility ID]],Operational[Facility ID],0)) -> 6220.56 | I5: =INDEX(Operational[Waste (tons)],MATCH(Emission8[[#This Row],[Facility ID]],Operational[Facility ID],0)) -> 70.1 | K5: IQR | L5: =L4-L3 -> 2430.8525
A6: F090 | B6: Reliance Industries | C6: 2022 Q2 | D6: Scope 3 | E6: CH₄ | F6: 605.59 | G6: =INDEX(Operational[Production Volume (units)],MATCH(Emission8[[#This Row],[Facility ID]],Operational[Facility ID],0)) -> 29895 | H6: =INDEX(Operational[Energy Consumption (MWh)],MATCH(Emission8[[#This Row],[Facility ID]],Operational[Facility ID],0)) -> 1631.08 | I6: =INDEX(Operational[Waste (tons)],MATCH(Emission8[[#This Row],[Facility ID]],Operational[Facility ID],0)) -> 39.93 | K6: LB | L6: =(L3-1.5*L5) -> -2249.6512
A7: F158 | B7: Tata Steel | C7: 2022 Q2 | D7: Scope 1 | E7: CH₄ | F7: 656.33 | G7: =INDEX(Operational[Production Volume (units)],MATCH(Emission8[[#This Row],[Facility ID]],Operational[Facility ID],0)) -> 61157 | H7: =INDEX(Operational[Energy Consumption (MWh)],MATCH(Emission8[[#This Row],[Facility ID]],Operational[Facility ID],0)) -> 7331.54 | I7: =INDEX(Operational[Waste (tons)],MATCH(Emission8[[#This Row],[Facility ID]],Operational[Facility ID],0)) -> 55.52 | K7: UB | L7: =(L4+1.5*L5) -> 7473.7587
A8: F023 | B8: L&T | C8: 2023 Q2 | D8: Scope 3 | E8: N₂O | F8: 4455.93 | G8: =INDEX(Operational[Production Volume (units)],MATCH(Emission8[[#This Row],[Facility ID]],Operational[Facility ID],0)) -> 47484 | H8: =INDEX(Operational[Energy Consumption (MWh)],MATCH(Emission8[[#This Row],[Facility ID]],Operational[Facility ID],0)) -> 3396.39 | I8: =INDEX(Operational[Waste (tons)],MATCH(Emission8[[#This Row],[Facility ID]],Operational[Facility ID],0)) -> 19.51
A9: F153 | B9: Tata Steel | C9: 2022 Q2 | D9: Scope 3 | E9: CH₄ | F9: 660.2 | G9: =INDEX(Operational[Production Volume (units)],MATCH(Emission8[[#This Row],[Facility ID]],Operational[Facility ID],0)) -> 95306 | H9: =INDEX(Operational[Energy Consumption (MWh)],MATCH(Emission8[[#This Row],[Facility ID]],Operational[Facility ID],0)) -> 9037.76 | I9: =INDEX(Operational[Waste (tons)],MATCH(Emission8[[#This Row],[Facility ID]],Operational[Facility ID],0)) -> 13.35 | K9: 2. Production Volume Units Outliers
A10: F079 | B10: Reliance Industries | C10: 2023 Q2 | D10: Scope 3 | E10: CH₄ | F10: 1883.3 | G10: =INDEX(Operational[Production Volume (units)],MATCH(Emission8[[#This Row],[Facility ID]],Operational[Facility ID],0)) -> 17311 | H10: =INDEX(Operational[Energy Consumption (MWh)],MATCH(Emission8[[#This Row],[Facility ID]],Operational[Facility ID],0)) -> 2257.38 | I10: =INDEX(Operational[Waste (tons)],MATCH(Emission8[[#This Row],[Facility ID]],Operational[Facility ID],0)) -> 91.07 | K10: Q1 | L10: =_xlfn.QUARTILE.EXC(Emission8[Production Volume (units)],1) -> 32131
A11: F065 | B11: L&T | C11: 2022 Q1 | D11: Scope 2 | E11: N₂O | F11: 221.01 | G11: =INDEX(Operational[Production Volume (units)],MATCH(Emission8[[#This Row],[Facility ID]],Operational[Facility ID],0)) -> 91031 | H11: =INDEX(Operational[Energy Consumption (MWh)],MATCH(Emission8[[#This Row],[Facility ID]],Operational[Facility ID],0)) -> 1783.57 | I11: =INDEX(Operational[Waste (tons)],MATCH(Emission8[[#This Row],[Facility ID]],Operational[Facility ID],0)) -> 32.05 | K11: Q3 | L11: =_xlfn.QUARTILE.EXC(Production_Volume__units,3) -> 77326.75
A12: F025 | B12: Adani Green | C12: 2022 Q1 | D12: Scope 2 | E12: CH₄ | F12: 4737.06 | G12: =INDEX(Operational[Production Volume (units)],MATCH(Emission8[[#This Row],[Facility ID]],Operational[Facility ID],0)) -> 32131 | H12: =INDEX(Operational[Energy Consumption (MWh)],MATCH(Emission8[[#This Row],[Facility ID]],Operational[Facility ID],0)) -> 1474.23 | I12: =INDEX(Operational[Waste (tons)],MATCH(Emission8[[#This Row],[Facility ID]],Operational[Facility ID],0)) -> 45.47 | K12: IQR | L12: =L11-L10 -> 45195.75
A13: F104 | B13: Adani Green | C13: 2022 Q1 | D13: Scope 3 | E13: N₂O | F13: 1951.28 | G13: =INDEX(Operational[Production Volume (units)],MATCH(Emission8[[#This Row],[Facility ID]],Operational[Facility ID],0)) -> 84851 | H13: =INDEX(Operational[Energy Consumption (MWh)],MATCH(Emission8[[#This Row],[Facility ID]],Operational[Facility ID],0)) -> 560.75 | I13: =INDEX(Operational[Waste (tons)],MATCH(Emission8[[#This Row],[Facility ID]],Operational[Facility ID],0)) -> 80.23 | K13: LB | L13: =(L10-1.5*L12) -> -35662.625
A14: F137 | B14: JSW Energy | C14: 2022 Q2 | D14: Scope 2 | E14: CH₄ | F14: 4320.11 | G14: =INDEX(Operational[Production Volume (units)],MATCH(Emission8[[#This Row],[Facility ID]],Operational[Facility ID],0)) -> 10933 | H14: =INDEX(Operational[Energy Consumption (MWh)],MATCH(Emission8[[#This Row],[Facility ID]],Operational[Facility ID],0)) -> 9004.37 | I14: =INDEX(Operational[Waste (tons)],MATCH(Emission8[[#This Row],[Facility ID]],Operational[Facility ID],0)) -> 26.84 | K14: UB | L14: =(L11+1.5*L12) -> 145120.38
A15: F158 | B15: Tata Steel | C15: 2022 Q1 | D15: Scope 2 | E15: CO₂ | F15: 2179.33 | G15: =INDEX(Operational[Production Volume (units)],MATCH(Emission8[[#This Row],[Facility ID]],Operational[Facility ID],0)) -> 61157 | H15: =INDEX(Operational[Energy Consumption (MWh)],MATCH(Emission8[[#This Row],[Facility ID]],Operational[Facility ID],0)) -> 7331.54 | I15: =INDEX(Operational[Waste (tons)],MATCH(Emission8[[#This Row],[Facility ID]],Operational[Facility ID],0)) -> 55.52
A16: F101 | B16: Tata Steel | C16: 2023 Q1 | D16: Scope 1 | E16: CH₄ | F16: 3612.19 | G16: =INDEX(Operational[Production Volume (units)],MATCH(Emission8[[#This Row],[Facility ID]],Operational[Facility ID],0)) -> 65719 | H16: =INDEX(Operational[Energy Consumption (MWh)],MATCH(Emission8[[#This Row],[Facility ID]],Operational[Facility ID],0)) -> 9362.41 | I16: =INDEX(Operational[Waste (tons)],MATCH(Emission8[[#This Row],[Facility ID]],Operational[Facility ID],0)) -> 86.55 | K16: 3. Energy Consumption (MWh)
A17: F194 | B17: Tata Steel | C17: 2022 Q1 | D17: Scope 2 | E17: N₂O | F17: 1270.36 | G17: =INDEX(Operational[Production Volume (units)],MATCH(Emission8[[#This Row],[Facility ID]],Operational[Facility ID],0)) -> 42382 | H17: =INDEX(Operational[Energy Consumption (MWh)],MATCH(Emission8[[#This Row],[Facility ID]],Operational[Facility ID],0)) -> 5116.69 | I17: =INDEX(Operational[Waste (tons)],MATCH(Emission8[[#This Row],[Facility ID]],Operational[Facility ID],0)) -> 80.42 | K17: Q1 | L17: =_xlfn.QUARTILE.EXC(Energy_Consumption__MWh,1) -> 3167.52
A18: F057 | B18: L&T | C18: 2023 Q2 | D18: Scope 2 | E18: CH₄ | F18: 1630.06 | G18: =INDEX(Operational[Production Volume (units)],MATCH(Emission8[[#This Row],[Facility ID]],Operational[Facility ID],0)) -> 40226 | H18: =INDEX(Operational[Energy Consumption (MWh)],MATCH(Emission8[[#This Row],[Facility ID]],Operational[Facility ID],0)) -> 7868.86 | I18: =INDEX(Operational[Waste (tons)],MATCH(Emission8[[#This Row],[Facility ID]],Operational[Facility ID],0)) -> 80.53 | K18: Q3 | L18: =_xlfn.QUARTILE.EXC(Energy_Consumption__MWh,3) -> 7574.39
A19: F017 | B19: Reliance Industries | C19: 2023 Q1 | D19: Scope 3 | E19: N₂O | F19: 3063.61 | G19: =INDEX(Operational[Production Volume (units)],MATCH(Emission8[[#This Row],[Facility ID]],Operational[Facility ID],0)) -> 71747 | H19: =INDEX(Operational[Energy Consumption (MWh)],MATCH(Emission8[[#This Row],[Facility ID]],Operational[Facility ID],0)) -> 9838.66 | I19: =INDEX(Operational[Waste (tons)],MATCH(Emission8[[#This Row],[Facility ID]],Operational[Facility ID],0)) -> 7.25 | K19: IQR | L19: =L18-L17 -> 4406.87
A20: F120 | B20: Adani Green | C20: 2022 Q1 | D20: Scope 3 | E20: N₂O | F20: 2447.42 | G20: =INDEX(Operational[Production Volume (units)],MATCH(Emission8[[#This Row],[Facility ID]],Operational[Facility ID],0)) -> 57215 | H20: =INDEX(Operational[Energy Consumption (MWh)],MATCH(Emission8[[#This Row],[Facility ID]],Operational[Facility ID],0)) -> 3227.1 | I20: =INDEX(Operational[Waste (tons)],MATCH(Emission8[[#This Row],[Facility ID]],Operational[Facility ID],0)) -> 32.91 | K20: LB | L20: =(L17-1.5*L19) -> -3442.785
A21: F139 | B21: JSW Energy | C21: 2022 Q2 | D21: Scope 2 | E21: N₂O | F21: 4170.13 | G21: =INDEX(Operational[Production Volume (units)],MATCH(Emission8[[#This Row],[Facility ID]],Operational[Facility ID],0)) -> 80904 | H21: =INDEX(Operational[Energy Consumption (MWh)],MATCH(Emission8[[#This Row],[Facility ID]],Operational[Facility ID],0)) -> 3263.09 | I21: =INDEX(Operational[Waste (tons)],MATCH(Emission8[[#This Row],[Facility ID]],Operational[Facility ID],0)) -> 58.37 | K21: UB | L21: =(L18+1.5*L19) -> 14184.695
A22: F166 | B22: Tata Steel | C22: 2023 Q2 | D22: Scope 3 | E22: CO₂ | F22: 2099.64 | G22: =INDEX(Operational[Production Volume (units)],MATCH(Emission8[[#This Row],[Facility ID]],Operational[Facility ID],0)) -> 96474 | H22: =INDEX(Operational[Energy Consumption (MWh)],MATCH(Emission8[[#This Row],[Facility ID]],Operational[Facility ID],0)) -> 7574.39 | I22: =INDEX(Operational[Waste (tons)],MATCH(Emission8[[#This Row],[Facility ID]],Operational[Facility ID],0)) -> 95.54
A23: F005 | B23: Adani Green | C23: 2023 Q2 | D23: Scope 2 | E23: CO₂ | F23: 3701.02 | G23: =INDEX(Operational[Production Volume (units)],MATCH(Emission8[[#This Row],[Facility ID]],Operational[Facility ID],0)) -> 61743 | H23: =INDEX(Operational[Energy Consumption (MWh)],MATCH(Emission8[[#This Row],[Facility ID]],Operational[Facility ID],0)) -> 7426.75 | I23: =INDEX(Operational[Waste (tons)],MATCH(Emission8[[#This Row],[Facility ID]],Operational[Facility ID],0)) -> 26.39 | K23: 4. Waste (tons)
A24: F060 | B24: Adani Green | C24: 2023 Q2 | D24: Scope 2 | E24: CH₄ | F24: 1262.77 | G24: =INDEX(Operational[Production Volume (units)],MATCH(Emission8[[#This Row],[Facility ID]],Operational[Facility ID],0)) -> 41539 | H24: =INDEX(Operational[Energy Consumption (MWh)],MATCH(Emission8[[#This Row],[Facility ID]],Operational[Facility ID],0)) -> 982.8 | I24: =INDEX(Operational[Waste (tons)],MATCH(Emission8[[#This Row],[Facility ID]],Operational[Facility ID],0)) -> 79.7 | K24: Q1 | L24: =_xlfn.QUARTILE.EXC(Waste__tons,1) -> 32.78
A25: F133 | B25: Reliance Industries | C25: 2022 Q1 | D25: Scope 1 | E25: N₂O | F25: 2741.92 | G25: =INDEX(Operational[Production Volume (units)],MATCH(Emission8[[#This Row],[Facility ID]],Operational[Facility ID],0)) -> 41168 | H25: =INDEX(Operational[Energy Consumption (MWh)],MATCH(Emission8[[#This Row],[Facility ID]],Operational[Facility ID],0)) -> 8226.77 | I25: =INDEX(Operational[Waste (tons)],MATCH(Emission8[[#This Row],[Facility ID]],Operational[Facility ID],0)) -> 42.55 | K25: Q3 | L25: =_xlfn.QUARTILE.EXC(Waste__tons,3) -> 75.46
A26: F025 | B26: Adani Green | C26: 2022 Q1 | D26: Scope 1 | E26: N₂O | F26: 1824.14 | G26: =INDEX(Operational[Production Volume (units)],MATCH(Emission8[[#This Row],[Facility ID]],Operational[Facility ID],0)) -> 32131 | H26: =INDEX(Operational[Energy Consumption (MWh)],MATCH(Emission8[[#This Row],[Facility ID]],Operational[Facility ID],0)) -> 1474.23 | I26: =INDEX(Operational[Waste (tons)],MATCH(Emission8[[#This Row],[Facility ID]],Operational[Facility ID],0)) -> 45.47 | K26: IQR | L26: =L25-L24 -> 42.68
A27: F134 | B27: Tata Steel | C27: 2023 Q2 | D27: Scope 3 | E27: CH₄ | F27: 738.44 | G27: =INDEX(Operational[Production Volume (units)],MATCH(Emission8[[#This Row],[Facility ID]],Operational[Facility ID],0)) -> 16256 | H27: =INDEX(Operational[Energy Consumption (MWh)],MATCH(Emission8[[#This Row],[Facility ID]],Operational[Facility ID],0)) -> 2127.18 | I27: =INDEX(Operational[Waste (tons)],MATCH(Emission8[[#This Row],[Facility ID]],Operational[Facility ID],0)) -> 38.94 | K27: LB | L27: =(L24-1.5*L26) -> -31.24
A28: F030 | B28: JSW Energy | C28: 2022 Q2 | D28: Scope 3 | E28: CO₂ | F28: 2856.76 | G28: =INDEX(Operational[Production Volume (units)],MATCH(Emission8[[#This Row],[Facility ID]],Operational[Facility ID],0)) -> 49924 | H28: =INDEX(Operational[Energy Consumption (MWh)],MATCH(Emission8[[#This Row],[Facility ID]],Operational[Facility ID],0)) -> 2199.16 | I28: =INDEX(Operational[Waste (tons)],MATCH(Emission8[[#This Row],[Facility ID]],Operational[Facility ID],0)) -> 75.48 | K28: UB | L28: =(L25+1.5*L26) -> 139.48
A29: F091 | B29: Adani Green | C29: 2022 Q2 | D29: Scope 1 | E29: N₂O | F29: 1787.35 | G29: =INDEX(Operational[Production Volume (units)],MATCH(Emission8[[#This Row],[Facility ID]],Operational[Facility ID],0)) -> 43490 | H29: =INDEX(Operational[Energy Consumption (MWh)],MATCH(Emission8[[#This Row],[Facility ID]],Operational[Facility ID],0)) -> 9300.88 | I29: =INDEX(Operational[Waste (tons)],MATCH(Emission8[[#This Row],[Facility ID]],Operational[Facility ID],0)) -> 58.43
A30: F002 | B30: Adani Green | C30: 2023 Q2 | D30: Scope 3 | E30: CO₂ | F30: 5138.83 | G30: =INDEX(Operational[Production Volume (units)],MATCH(Emission8[[#This Row],[Facility ID]],Operational[Facility ID],0)) -> 53661 | H30: =INDEX(Operational[Energy Consumption (MWh)],MATCH(Emission8[[#This Row],[Facility ID]],Operational[Facility ID],0)) -> 6965.81 | I30: =INDEX(Operational[Waste (tons)],MATCH(Emission8[[#This Row],[Facility ID]],Operational[Facility ID],0)) -> 69.4 | K30: No any outliers
A31: F121 | B31: Tata Steel | C31: 2022 Q1 | D31: Scope 3 | E31: CH₄ | F31: 5005.44 | G31: =INDEX(Operational[Production Volume (units)],MATCH(Emission8[[#This Row],[Facility ID]],Operational[Facility ID],0)) -> 11952 | H31: =INDEX(Operational[Energy Consumption (MWh)],MATCH(Emission8[[#This Row],[Facility ID]],Operational[Facility ID],0)) -> 4637.74 | I31: =INDEX(Operational[Waste (tons)],MATCH(Emission8[[#This Row],[Facility ID]],Operational[Facility ID],0)) -> 63.78
A32: F008 | B32: Tata Steel | C32: 2023 Q2 | D32: Scope 2 | E32: N₂O | F32: 4053.3 | G32: =INDEX(Operational[Production Volume (units)],MATCH(Emission8[[#This Row],[Facility ID]],Operational[Facility ID],0)) -> 50306 | H32: =INDEX(Operational[Energy Consumption (MWh)],MATCH(Emission8[[#This Row],[Facility ID]],Operational[Facility ID],0)) -> 7031.37 | I32: =INDEX(Operational[Waste (tons)],MATCH(Emission8[[#This Row],[Facility ID]],Operational[Facility ID],0)) -> 13.27
A33: F198 | B33: Tata Steel | C33: 2023 Q2 | D33: Scope 2 | E33: N₂O | F33: 280.72 | G33: =INDEX(Operational[Production Volume (units)],MATCH(Emission8[[#This Row],[Facility ID]],Operational[Facility ID],0)) -> 40577 | H33: =INDEX(Operational[Energy Consumption (MWh)],MATCH(Emission8[[#This Row],[Facility ID]],Operational[Facility ID],0)) -> 4280.82 | I33: =INDEX(Operational[Waste (tons)],MATCH(Emission8[[#This Row],[Facility ID]],Operational[Facility ID],0)) -> 79.88
A34: F087 | B34: Adani Green | C34: 2023 Q2 | D34: Scope 1 | E34: N₂O | F34: 329.41 | G34: =INDEX(Operational[Production Volume (units)],MATCH(Emission8[[#This Row],[Facility ID]],Operational[Facility ID],0)) -> 44164 | H34: =INDEX(Operational[Energy Consumption (MWh)],MATCH(Emission8[[#This Row],[Facility ID]],Operational[Facility ID],0)) -> 3869.32 | I34: =INDEX(Operational[Waste (tons)],MATCH(Emission8[[#This Row],[Facility ID]],Operational[Facility ID],0)) -> 13.81
A35: F175 | B35: Tata Steel | C35: 2022 Q2 | D35: Scope 1 | E35: CO₂ | F35: 4133.74 | G35: =INDEX(Operational[Production Volume (units)],MATCH(Emission8[[#This Row],[Facility ID]],Operational[Facility ID],0)) -> 94949 | H35: =INDEX(Operational[Energy Consumption (MWh)],MATCH(Emission8[[#This Row],[Facility ID]],Operational[Facility ID],0)) -> 9714.76 | I35: =INDEX(Operational[Waste (tons)],MATCH(Emission8[[#This Row],[Facility ID]],Operational[Facility ID],0)) -> 64.9
A36: F100 | B36: JSW Energy | C36: 2023 Q1 | D36: Scope 2 | E36: CO₂ | F36: 2773.3 | G36: =INDEX(Operational[Production Volume (units)],MATCH(Emission8[[#This Row],[Facility ID]],Operational[Facility ID],0)) -> 90632 | H36: =INDEX(Operational[Energy Consumption (MWh)],MATCH(Emission8[[#This Row],[Facility ID]],Operational[Facility ID],0)) -> 5292.17 | I36: =INDEX(Operational[Waste (tons)],MATCH(Emission8[[#This Row],[Facility ID]],Operational[Facility ID],0)) -> 78.45
A37: F042 | B37: L&T | C37: 2022 Q2 | D37: Scope 3 | E37: CH₄ | F37: 3482.08 | G37: =INDEX(Operational[Production Volume (units)],MATCH(Emission8[[#This Row],[Facility ID]],Operational[Facility ID],0)) -> 58111 | H37: =INDEX(Operational[Energy Consumption (MWh)],MATCH(Emission8[[#This Row],[Facility ID]],Operational[Facility ID],0)) -> 4610.9 | I37: =INDEX(Operational[Waste (tons)],MATCH(Emission8[[#This Row],[Facility ID]],Operational[Facility ID],0)) -> 21.53
A38: F173 | B38: L&T | C38: 2023 Q1 | D38: Scope 3 | E38: CH₄ | F38: 1953.71 | G38: =INDEX(Operational[Production Volume (units)],MATCH(Emission8[[#This Row],[Facility ID]],Operational[Facility ID],0)) -> 38181 | H38: =INDEX(Operational[Energy Consumption (MWh)],MATCH(Emission8[[#This Row],[Facility ID]],Operational[Facility ID],0)) -> 691.84 | I38: =INDEX(Operational[Waste (tons)],MATCH(Emission8[[#This Row],[Facility ID]],Operational[Facility ID],0)) -> 33.53
A39: F025 | B39: Adani Green | C39: 2023 Q1 | D39: Scope 1 | E39: CO₂ | F39: 4444.76 | G39: =INDEX(Operational[Production Volume (units)],MATCH(Emission8[[#This Row],[Facility ID]],Operational[Facility ID],0)) -> 32131 | H39: =INDEX(Operational[Energy Consumption (MWh)],MATCH(Emission8[[#This Row],[Facility ID]],Operational[Facility ID],0)) -> 1474.23 | I39: =INDEX(Operational[Waste (tons)],MATCH(Emission8[[#This Row],[Facility ID]],Operational[Facility ID],0)) -> 45.47
A40: F173 | B40: L&T | C40: 2023 Q2 | D40: Scope 2 | E40: CO₂ | F40: 1836.99 | G40: =INDEX(Operational[Production Volume (units)],MATCH(Emission8[[#This Row],[Facility ID]],Operational[Facility ID],0)) -> 38181 | H40: =INDEX(Operational[Energy Consumption (MWh)],MATCH(Emission8[[#This Row],[Facility ID]],Operational[Facility ID],0)) -> 691.84 | I40: =INDEX(Operational[Waste (tons)],MATCH(Emission8[[#This Row],[Facility ID]],Operational[Facility ID],0)) -> 33.53
...

Sheet Merge operational & suppliar
A1: Facility ID | B1: Facility Name | C1: Reporting Period | D1: Scope | E1: GHG Type | F1: Emissions (tons) | G1: Production Volume (units) | H1: Energy Consumption (MWh) | I1: Waste (tons) | J1: Estimated Carbon Footprint (tons CO₂e) | K1: Income Distribution (%)
A2: F088 | B2: JSW Energy | C2: 2022 Q1 | D2: Scope 3 | E2: CH₄ | F2: 2435.6 | G2: 77330 | H2: 6936.58 | I2: 82.3 | J2: =IFERROR(INDEX(Suppliar[Estimated Carbon Footprint (tons CO₂e)],MATCH('Merge operational & suppliar'!A2,Suppliar[Facility ID],0)),"") -> 264.23 | K2: =IFERROR(INDEX(Suppliar[Income Distribution (%)],MATCH('Merge operational & suppliar'!A2,Suppliar[Facility ID],0)),"") -> 28.19
A3: F021 | B3: L&T | C3: 2022 Q2 | D3: Scope 1 | E3: CO₂ | F3: 835.45 | G3: 44657 | H3: 7867.98 | I3: 96.01 | J3: =IFERROR(INDEX(Suppliar[Estimated Carbon Footprint (tons CO₂e)],MATCH('Merge operational & suppliar'!A3,Suppliar[Facility ID],0)),"") -> 694.92 | K3: =IFERROR(INDEX(Suppliar[Income Distribution (%)],MATCH('Merge operational & suppliar'!A3,Suppliar[Facility ID],0)),"") -> 26.24
A4: F107 | B4: Reliance Industries | C4: 2022 Q2 | D4: Scope 1 | E4: CO₂ | F4: 3430.45 | G4: 43512 | H4: 5352.18 | I4: 6.17 | J4: =IFERROR(INDEX(Suppliar[Estimated Carbon Footprint (tons CO₂e)],MATCH('Merge operational & suppliar'!A4,Suppliar[Facility ID],0)),"") -> 311.36 | K4: =IFERROR(INDEX(Suppliar[Income Distribution (%)],MATCH('Merge operational & suppliar'!A4,Suppliar[Facility ID],0)),"") -> 28.72
A5: F106 | B5: Tata Steel | C5: 2022 Q1 | D5: Scope 1 | E5: CO₂ | F5: 4214.24 | G5: 98682 | H5: 6220.56 | I5: 70.1 | J5: =IFERROR(INDEX(Suppliar[Estimated Carbon Footprint (tons CO₂e)],MATCH('Merge operational & suppliar'!A5,Suppliar[Facility ID],0)),"") -> 724.63 | K5: =IFERROR(INDEX(Suppliar[Income Distribution (%)],MATCH('Merge operational & suppliar'!A5,Suppliar[Facility ID],0)),"") -> 27.81
A6: F090 | B6: Reliance Industries | C6: 2022 Q2 | D6: Scope 3 | E6: CH₄ | F6: 605.59 | G6: 29895 | H6: 1631.08 | I6: 39.93 | J6: =IFERROR(INDEX(Suppliar[Estimated Carbon Footprint (tons CO₂e)],MATCH('Merge operational & suppliar'!A6,Suppliar[Facility ID],0)),"") -> 959.2 | K6: =IFERROR(INDEX(Suppliar[Income Distribution (%)],MATCH('Merge operational & suppliar'!A6,Suppliar[Facility ID],0)),"") -> 38.84
A7: F158 | B7: Tata Steel | C7: 2022 Q2 | D7: Scope 1 | E7: CH₄ | F7: 656.33 | G7: 61157 | H7: 7331.54 | I7: 55.52 | J7: =IFERROR(INDEX(Suppliar[Estimated Carbon Footprint (tons CO₂e)],MATCH('Merge operational & suppliar'!A7,Suppliar[Facility ID],0)),"") -> 783.77 | K7: =IFERROR(INDEX(Suppliar[Income Distribution (%)],MATCH('Merge operational & suppliar'!A7,Suppliar[Facility ID],0)),"") -> 31.59
A8: F023 | B8: L&T | C8: 2023 Q2 | D8: Scope 3 | E8: N₂O | F8: 4455.93 | G8: 47484 | H8: 3396.39 | I8: 19.51 | J8: =IFERROR(INDEX(Suppliar[Estimated Carbon Footprint (tons CO₂e)],MATCH('Merge operational & suppliar'!A8,Suppliar[Facility ID],0)),"") -> 790.74 | K8: =IFERROR(INDEX(Suppliar[Income Distribution (%)],MATCH('Merge operational & suppliar'!A8,Suppliar[Facility ID],0)),"") -> 12.77
A9: F153 | B9: Tata Steel | C9: 2022 Q2 | D9: Scope 3 | E9: CH₄ | F9: 660.2 | G9: 95306 | H9: 9037.76 | I9: 13.35 | J9: =IFERROR(INDEX(Suppliar[Estimated Carbon Footprint (tons CO₂e)],MATCH('Merge operational & suppliar'!A9,Suppliar[Facility ID],0)),"") -> 724.63 | K9: =IFERROR(INDEX(Suppliar[Income Distribution (%)],MATCH('Merge operational & suppliar'!A9,Suppliar[Facility ID],0)),"") -> 21.2
A10: F079 | B10: Reliance Industries | C10: 2023 Q2 | D10: Scope 3 | E10: CH₄ | F10: 1883.3 | G10: 17311 | H10: 2257.38 | I10: 91.07 | J10: =IFERROR(INDEX(Suppliar[Estimated Carbon Footprint (tons CO₂e)],MATCH('Merge operational & suppliar'!A10,Suppliar[Facility ID],0)),"") -> 341.24 | K10: =IFERROR(INDEX(Suppliar[Income Distribution (%)],MATCH('Merge operational & suppliar'!A10,Suppliar[Facility ID],0)),"") -> 80.69
A11: F065 | B11: L&T | C11: 2022 Q1 | D11: Scope 2 | E11: N₂O | F11: 221.01 | G11: 91031 | H11: 1783.57 | I11: 32.05 | J11: =IFERROR(INDEX(Suppliar[Estimated Carbon Footprint (tons CO₂e)],MATCH('Merge operational & suppliar'!A11,Suppliar[Facility ID],0)),"") -> 532.27 | K11: =IFERROR(INDEX(Suppliar[Income Distribution (%)],MATCH('Merge operational & suppliar'!A11,Suppliar[Facility ID],0)),"") -> 15.2
A12: F025 | B12: Adani Green | C12: 2022 Q1 | D12: Scope 2 | E12: CH₄ | F12: 4737.06 | G12: 32131 | H12: 1474.23 | I12: 45.47 | J12: =IFERROR(INDEX(Suppliar[Estimated Carbon Footprint (tons CO₂e)],MATCH('Merge operational & suppliar'!A12,Suppliar[Facility ID],0)),"") -> 830.73 | K12: =IFERROR(INDEX(Suppliar[Income Distribution (%)],MATCH('Merge operational & suppliar'!A12,Suppliar[Facility ID],0)),"") -> 17.97
A13: F104 | B13: Adani Green | C13: 2022 Q1 | D13: Scope 3 | E13: N₂O | F13: 1951.28 | G13: 84851 | H13: 560.75 | I13: 80.23 | J13: =IFERROR(INDEX(Suppliar[Estimated Carbon Footprint (tons CO₂e)],MATCH('Merge operational & suppliar'!A13,Suppliar[Facility ID],0)),"") -> 610.8 | K13: =IFERROR(INDEX(Suppliar[Income Distribution (%)],MATCH('Merge operational & suppliar'!A13,Suppliar[Facility ID],0)),"") -> 26.58
... A2001: F018 | B2001: Adani Green | C2001: 2023 Q1 | D2001: Scope 2 | E2001: N₂O | F2001: 2433.04 | G2001: 69305 | H2001: 3203.67 | I2001: 83.65 | J2001: =IFERROR(INDEX(Suppliar[Estimated Carbon Footprint (tons CO₂e)],MATCH('Merge operational & suppliar'!A2001,Suppliar[Facility ID],0)),"") -> 173.67 | K2001: =IFERROR(INDEX(Suppliar[Income Distribution (%)],MATCH('Merge operational & suppliar'!A2001,Suppliar[Facility ID],0)),"") -> 67.04

Sheet Merge Pivot Table
A1: 1. Facility name & GHG Type by Emissions | G1: 2. Facility and Production volume | J1: 3. Facility by Energy consumption | M1: 4. Facility by Estimated Carbon Footprint (tons CO₂e) | P1: 5. Production and Energy
A3: Sum of Emissions (tons) | B3: Column Labels | G3: Row Labels | H3: Sum of Production Volume (units) | J3: Row Labels | K3: Sum of Energy Consumption (MWh) | M3: Row Labels | N3: Sum of Estimated Carbon Footprint (tons CO₂e) | P3: Facility Name | Q3: Sum of Production Volume (units) | R3: Sum of Energy Consumption (MWh) | S3: Energy Per Unit
A4: Row Labels | B4: CH₄ | C4: CO₂ | D4: N₂O | E4: Grand Total | G4: Adani Green | H4: 29395528 | J4: Adani Green | K4: 2444660.2 | M4: Tata Steel | N4: 262199.11 | P4: Adani Green | Q4: 29395528 | R4: 2444660.2 | S4: =R4/Q4 -> 0.083164357
A5: Adani Green | B5: 409046.19 | C5: 511555.97 | D5: 440511.14 | E5: 1361113.3 | G5: Tata Steel | H5: 24049193 | J5: Tata Steel | K5: 2326032.9 | M5: Adani Green | N5: 251594.08 | P5: Tata Steel | Q5: 24049193 | R5: 2326032.9 | S5: =R5/Q5 -> 0.096719789
A6: Tata Steel | B6: 389204.06 | C6: 378060.21 | D6: 360735.81 | E6: 1128000.1 | G6: Reliance Industries | H6: 20229730 | J6: Reliance Industries | K6: 2061199.3 | M6: Reliance Industries | N6: 197162.78 | P6: Reliance Industries | Q6: 20229730 | R6: 2061199.3 | S6: =R6/Q6 -> 0.10188961
A7: Reliance Industries | B7: 302079.13 | C7: 311467.25 | D7: 351143.19 | E7: 964689.57 | G7: JSW Energy | H7: 18553960 | J7: JSW Energy | K7: 2036685.5 | M7: JSW Energy | N7: 192442.16 | P7: JSW Energy | Q7: 18553960 | R7: 2036685.5 | S7: =R7/Q7 -> 0.10977093
A8: JSW Energy | B8: 317426.2 | C8: 361846.78 | D8: 267241.47 | E8: 946514.45 | G8: L&T | H8: 16508296 | J8: L&T | K8: 1915633.5 | M8: L&T | N8: 149337.41 | P8: L&T | Q8: 16508296 | R8: 1915633.5 | S8: =R8/Q8 -> 0.11604066
A9: L&T | B9: 292290.35 | C9: 232865.04 | D9: 290919.2 | E9: 816074.59 | G9: Grand Total | H9: 108736707 | J9: Grand Total | K9: 10784211 | M9: Grand Total | N9: 1052735.5
A10: Grand Total | B10: 1710045.9 | C10: 1795795.2 | D10: 1710550.8 | E10: 5216392

Sheet Dashboard
